{
    "registryname": "fuser",
    "localizedname": "聚变反应堆",
    "requires-blueprint": true,
    "color": "005017",
    "parts": [
        {
            "x": 0,
            "y": 0,
            "z": 0,
            "elements": [
                "modularmachinery:blockcontroller@2"
            ]
        },
        {
            "x": -1,
            "y": 0,
            "z": 0,
            "elements": [
                "modularmachinery:blockcasing@4"
            ]
        },
        {
            "x": 1,
            "y": 2,
            "z": 1,
            "elements": [
                "environmentaltech:erodium_slab@0"
            ]
        },
        {
            "x": 1,
            "y": 0,
            "z": 0,
            "elements": [
                "modularmachinery:blockcasing@4"
            ]
        },
        {
            "x": -4,
            "y": -2,
            "z": 7,
            "elements": [
                "mekanismgenerators:reactorglass@0"
            ]
        },
        {
            "x": -3,
            "y": 0,
            "z": 8,
            "elements": [
                "mekanismgenerators:reactorglass@0"
            ]
        },
        {
            "x": -2,
            "y": 2,
            "z": 9,
            "elements": [
                "environmentaltech:erodium_slab@0"
            ]
        },
        {
            "x": -1,
            "y": 2,
            "z": 9,
            "elements": [
                "modularmachinery:blockcasing@4"
            ]
        },
        {
            "x": 0,
            "y": 2,
            "z": 9,
            "elements": [
                "modularmachinery:blockcasing@4"
            ]
        },
        {
            "x": 1,
            "y": 2,
            "z": 9,
            "elements": [
                "modularmachinery:blockcasing@4"
            ]
        },
        {
            "x": 0,
            "y": -2,
            "z": 7,
            "elements": [
                "environmentaltech:pladium@0"
            ]
        },
        {
            "x": 2,
            "y": 2,
            "z": 9,
            "elements": [
                "environmentaltech:erodium_slab@0"
            ]
        },
        {
            "x": 3,
            "y": 0,
            "z": 8,
            "elements": [
                "mekanismgenerators:reactorglass@0"
            ]
        },
        {
            "x": 4,
            "y": -2,
            "z": 7,
            "elements": [
                "mekanismgenerators:reactorglass@0"
            ]
        },
        {
            "x": 1,
            "y": -1,
            "z": 0,
            "elements": [
                "modularmachinery:blockcasing@4"
            ]
        },
        {
            "x": 0,
            "y": -1,
            "z": 0,
            "elements": [
                "modularmachinery:blockinputbus@4"
            ]
        },
        {
            "x": -1,
            "y": 1,
            "z": 0,
            "elements": [
                "mekanism:basicblock@2"
            ]
        },
        {
            "x": 0,
            "y": 1,
            "z": 0,
            "elements": [
                "mekanism:basicblock@2"
            ]
        },
        {
            "x": -1,
            "y": -1,
            "z": 0,
            "elements": [
                "modularmachinery:blockcasing@4"
            ]
        },
        {
            "x": 1,
            "y": 1,
            "z": 0,
            "elements": [
                "mekanism:basicblock@2"
            ]
        },
        {
            "x": -4,
            "y": -1,
            "z": 7,
            "elements": [
                "mekanismgenerators:reactorglass@0"
            ]
        },
        {
            "x": -3,
            "y": 1,
            "z": 8,
            "elements": [
                "mekanism:basicblock@2"
            ]
        },
        {
            "x": -4,
            "y": -3,
            "z": 6,
            "elements": [
                "mekanism:basicblock@2"
            ]
        },
        {
            "x": -3,
            "y": -3,
            "z": 6,
            "elements": [
                "modularmachinery:blockcasing@4"
            ]
        },
        {
            "x": -2,
            "y": -3,
            "z": 6,
            "elements": [
                "modularmachinery:blockcasing@4"
            ]
        },
        {
            "x": -1,
            "y": -3,
            "z": 6,
            "elements": [
                "modularmachinery:blockcasing@4"
            ]
        },
        {
            "x": 0,
            "y": -1,
            "z": 7,
            "elements": [
                "environmentaltech:pladium@0"
            ]
        },
        {
            "x": 0,
            "y": -3,
            "z": 6,
            "elements": [
                "mekanism:basicblock@0"
            ]
        },
        {
            "x": 3,
            "y": 1,
            "z": 8,
            "elements": [
                "mekanism:basicblock@2"
            ]
        },
        {
            "x": 1,
            "y": -3,
            "z": 6,
            "elements": [
                "modularmachinery:blockcasing@4"
            ]
        },
        {
            "x": 2,
            "y": -3,
            "z": 6,
            "elements": [
                "modularmachinery:blockcasing@4"
            ]
        },
        {
            "x": 4,
            "y": -1,
            "z": 7,
            "elements": [
                "mekanismgenerators:reactorglass@0"
            ]
        },
        {
            "x": 3,
            "y": -3,
            "z": 6,
            "elements": [
                "modularmachinery:blockcasing@4"
            ]
        },
        {
            "x": 4,
            "y": -3,
            "z": 6,
            "elements": [
                "mekanism:basicblock@2"
            ]
        },
        {
            "x": 1,
            "y": -2,
            "z": 0,
            "elements": [
                "modularmachinery:blockcasing@4"
            ]
        },
        {
            "x": 0,
            "y": -2,
            "z": 0,
            "elements": [
                "modularmachinery:blockfluidinputhatch@4"
            ]
        },
        {
            "x": -1,
            "y": 2,
            "z": 0,
            "elements": [
                "environmentaltech:erodium_slab@0"
            ]
        },
        {
            "x": 0,
            "y": 2,
            "z": 0,
            "elements": [
                "environmentaltech:erodium_slab@0"
            ]
        },
        {
            "x": -1,
            "y": -2,
            "z": 0,
            "elements": [
                "modularmachinery:blockcasing@4"
            ]
        },
        {
            "x": 1,
            "y": 2,
            "z": 0,
            "elements": [
                "environmentaltech:erodium_slab@0"
            ]
        },
        {
            "x": -4,
            "y": 0,
            "z": 7,
            "elements": [
                "mekanismgenerators:reactorglass@0"
            ]
        },
        {
            "x": -3,
            "y": 2,
            "z": 8,
            "elements": [
                "environmentaltech:erodium_slab@0"
            ]
        },
        {
            "x": -4,
            "y": -2,
            "z": 6,
            "elements": [
                "mekanismgenerators:reactorglass@0"
            ]
        },
        {
            "x": -2,
            "y": 2,
            "z": 8,
            "elements": [
                "modularmachinery:blockcasing@1"
            ]
        },
        {
            "x": -1,
            "y": 2,
            "z": 8,
            "elements": [
                "modularmachinery:blockcasing@1"
            ]
        },
        {
            "x": 0,
            "y": 2,
            "z": 8,
            "elements": [
                "modularmachinery:blockcasing@4"
            ]
        },
        {
            "x": -1,
            "y": -2,
            "z": 6,
            "elements": [
                "environmentaltech:pladium@0"
            ]
        },
        {
            "x": 0,
            "y": 0,
            "z": 7,
            "elements": [
                "environmentaltech:pladium@0"
            ]
        },
        {
            "x": 1,
            "y": 2,
            "z": 8,
            "elements": [
                "modularmachinery:blockcasing@1"
            ]
        },
        {
            "x": 0,
            "y": -2,
            "z": 6,
            "elements": [
                "mekanismgenerators:generator@9"
            ]
        },
        {
            "x": 2,
            "y": 2,
            "z": 8,
            "elements": [
                "modularmachinery:blockcasing@1"
            ]
        },
        {
            "x": 3,
            "y": 2,
            "z": 8,
            "elements": [
                "environmentaltech:erodium_slab@0"
            ]
        },
        {
            "x": 1,
            "y": -2,
            "z": 6,
            "elements": [
                "environmentaltech:pladium@0"
            ]
        },
        {
            "x": 4,
            "y": 0,
            "z": 7,
            "elements": [
                "mekanismgenerators:reactorglass@0"
            ]
        },
        {
            "x": 4,
            "y": -2,
            "z": 6,
            "elements": [
                "modularmachinery:blockfluidoutputhatch@4"
            ]
        },
        {
            "x": 1,
            "y": -3,
            "z": 0,
            "elements": [
                "modularmachinery:blockcasing@4"
            ]
        },
        {
            "x": 0,
            "y": -3,
            "z": 0,
            "elements": [
                "modularmachinery:blockenergyinputhatch@4"
            ]
        },
        {
            "x": -1,
            "y": -3,
            "z": 0,
            "elements": [
                "modularmachinery:blockcasing@4"
            ]
        },
        {
            "x": -4,
            "y": 1,
            "z": 7,
            "elements": [
                "mekanism:basicblock@2"
            ]
        },
        {
            "x": -4,
            "y": -1,
            "z": 6,
            "elements": [
                "mekanismgenerators:reactorglass@0"
            ]
        },
        {
            "x": -4,
            "y": -3,
            "z": 5,
            "elements": [
                "mekanism:basicblock@2"
            ]
        },
        {
            "x": -3,
            "y": -3,
            "z": 5,
            "elements": [
                "modularmachinery:blockcasing@4"
            ]
        },
        {
            "x": 0,
            "y": 1,
            "z": 7,
            "elements": [
                "environmentaltech:pladium@0"
            ]
        },
        {
            "x": -2,
            "y": -3,
            "z": 5,
            "elements": [
                "modularmachinery:blockcasing@2"
            ]
        },
        {
            "x": -1,
            "y": -1,
            "z": 6,
            "elements": [
                "environmentaltech:pladium@0"
            ]
        },
        {
            "x": -1,
            "y": -3,
            "z": 5,
            "elements": [
                "modularmachinery:blockcasing@3"
            ]
        },
        {
            "x": 0,
            "y": -1,
            "z": 6,
            "elements": [
                "mekanismgenerators:generator@9"
            ]
        },
        {
            "x": 0,
            "y": -3,
            "z": 5,
            "elements": [
                "modularmachinery:blockcasing@4"
            ]
        },
        {
            "x": 1,
            "y": -1,
            "z": 6,
            "elements": [
                "environmentaltech:pladium@0"
            ]
        },
        {
            "x": 1,
            "y": -3,
            "z": 5,
            "elements": [
                "modularmachinery:blockcasing@3"
            ]
        },
        {
            "x": 4,
            "y": 1,
            "z": 7,
            "elements": [
                "mekanism:basicblock@2"
            ]
        },
        {
            "x": 2,
            "y": -3,
            "z": 5,
            "elements": [
                "modularmachinery:blockcasing@2"
            ]
        },
        {
            "x": 4,
            "y": -1,
            "z": 6,
            "elements": [
                "modularmachinery:blockoutputbus@4"
            ]
        },
        {
            "x": 3,
            "y": -3,
            "z": 5,
            "elements": [
                "modularmachinery:blockcasing@4"
            ]
        },
        {
            "x": 4,
            "y": -3,
            "z": 5,
            "elements": [
                "mekanism:basicblock@2"
            ]
        },
        {
            "x": -4,
            "y": 2,
            "z": 7,
            "elements": [
                "environmentaltech:erodium_slab@0"
            ]
        },
        {
            "x": -4,
            "y": 0,
            "z": 6,
            "elements": [
                "mekanismgenerators:reactorglass@0"
            ]
        },
        {
            "x": -3,
            "y": 2,
            "z": 7,
            "elements": [
                "modularmachinery:blockcasing@4"
            ]
        },
        {
            "x": -4,
            "y": -2,
            "z": 5,
            "elements": [
                "mekanismgenerators:reactorglass@0"
            ]
        },
        {
            "x": -2,
            "y": 2,
            "z": 7,
            "elements": [
                "modularmachinery:blockcasing@1"
            ]
        },
        {
            "x": -1,
            "y": 2,
            "z": 7,
            "elements": [
                "modularmachinery:blockcasing@3"
            ]
        },
        {
            "x": 0,
            "y": 2,
            "z": 7,
            "elements": [
                "modularmachinery:blockcasing@4"
            ]
        },
        {
            "x": -1,
            "y": 0,
            "z": 6,
            "elements": [
                "environmentaltech:pladium@0"
            ]
        },
        {
            "x": 0,
            "y": 0,
            "z": 6,
            "elements": [
                "mekanismgenerators:generator@9"
            ]
        },
        {
            "x": 1,
            "y": 2,
            "z": 7,
            "elements": [
                "modularmachinery:blockcasing@3"
            ]
        },
        {
            "x": 0,
            "y": -2,
            "z": 5,
            "elements": [
                "environmentaltech:pladium@0"
            ]
        },
        {
            "x": 2,
            "y": 2,
            "z": 7,
            "elements": [
                "modularmachinery:blockcasing@1"
            ]
        },
        {
            "x": 1,
            "y": 0,
            "z": 6,
            "elements": [
                "environmentaltech:pladium@0"
            ]
        },
        {
            "x": 3,
            "y": 2,
            "z": 7,
            "elements": [
                "modularmachinery:blockcasing@4"
            ]
        },
        {
            "x": 4,
            "y": 2,
            "z": 7,
            "elements": [
                "environmentaltech:erodium_slab@0"
            ]
        },
        {
            "x": 4,
            "y": 0,
            "z": 6,
            "elements": [
                "mekanismgenerators:reactorglass@0"
            ]
        },
        {
            "x": 4,
            "y": -2,
            "z": 5,
            "elements": [
                "mekanismgenerators:reactorglass@0"
            ]
        },
        {
            "x": -4,
            "y": 1,
            "z": 6,
            "elements": [
                "mekanism:basicblock@2"
            ]
        },
        {
            "x": -4,
            "y": -1,
            "z": 5,
            "elements": [
                "mekanismgenerators:reactorglass@0"
            ]
        },
        {
            "x": -3,
            "y": -3,
            "z": 4,
            "elements": [
                "mekanism:basicblock@2"
            ]
        },
        {
            "x": -1,
            "y": 1,
            "z": 6,
            "elements": [
                "environmentaltech:pladium@0"
            ]
        },
        {
            "x": 0,
            "y": 1,
            "z": 6,
            "elements": [
                "mekanismgenerators:generator@9"
            ]
        },
        {
            "x": -2,
            "y": -3,
            "z": 4,
            "elements": [
                "modularmachinery:blockcasing@2"
            ]
        },
        {
            "x": -1,
            "y": -3,
            "z": 4,
            "elements": [
                "modularmachinery:blockcasing@2"
            ]
        },
        {
            "x": 0,
            "y": -1,
            "z": 5,
            "elements": [
                "environmentaltech:pladium@0"
            ]
        },
        {
            "x": 1,
            "y": 1,
            "z": 6,
            "elements": [
                "environmentaltech:pladium@0"
            ]
        },
        {
            "x": 0,
            "y": -3,
            "z": 4,
            "elements": [
                "modularmachinery:blockcasing@4"
            ]
        },
        {
            "x": 1,
            "y": -3,
            "z": 4,
            "elements": [
                "modularmachinery:blockcasing@2"
            ]
        },
        {
            "x": 4,
            "y": 1,
            "z": 6,
            "elements": [
                "mekanism:basicblock@2"
            ]
        },
        {
            "x": 2,
            "y": -3,
            "z": 4,
            "elements": [
                "modularmachinery:blockcasing@2"
            ]
        },
        {
            "x": 4,
            "y": -1,
            "z": 5,
            "elements": [
                "mekanismgenerators:reactorglass@0"
            ]
        },
        {
            "x": 3,
            "y": -3,
            "z": 4,
            "elements": [
                "mekanism:basicblock@2"
            ]
        },
        {
            "x": -4,
            "y": 2,
            "z": 6,
            "elements": [
                "environmentaltech:erodium_slab@0"
            ]
        },
        {
            "x": -4,
            "y": 0,
            "z": 5,
            "elements": [
                "mekanismgenerators:reactorglass@0"
            ]
        },
        {
            "x": -3,
            "y": 2,
            "z": 6,
            "elements": [
                "modularmachinery:blockcasing@4"
            ]
        },
        {
            "x": -2,
            "y": 2,
            "z": 6,
            "elements": [
                "modularmachinery:blockcasing@4"
            ]
        },
        {
            "x": -3,
            "y": -2,
            "z": 4,
            "elements": [
                "mekanismgenerators:reactorglass@0"
            ]
        },
        {
            "x": -1,
            "y": 2,
            "z": 6,
            "elements": [
                "modularmachinery:blockcasing@4"
            ]
        },
        {
            "x": 0,
            "y": 2,
            "z": 6,
            "elements": [
                "mekanism:basicblock@0"
            ]
        },
        {
            "x": 0,
            "y": 0,
            "z": 5,
            "elements": [
                "environmentaltech:pladium@0"
            ]
        },
        {
            "x": 1,
            "y": 2,
            "z": 6,
            "elements": [
                "modularmachinery:blockcasing@4"
            ]
        },
        {
            "x": 2,
            "y": 2,
            "z": 6,
            "elements": [
                "modularmachinery:blockcasing@4"
            ]
        },
        {
            "x": 3,
            "y": 2,
            "z": 6,
            "elements": [
                "modularmachinery:blockcasing@4"
            ]
        },
        {
            "x": 4,
            "y": 2,
            "z": 6,
            "elements": [
                "environmentaltech:erodium_slab@0"
            ]
        },
        {
            "x": 4,
            "y": 0,
            "z": 5,
            "elements": [
                "mekanismgenerators:reactorglass@0"
            ]
        },
        {
            "x": 3,
            "y": -2,
            "z": 4,
            "elements": [
                "mekanismgenerators:reactorglass@0"
            ]
        },
        {
            "x": -4,
            "y": 1,
            "z": 5,
            "elements": [
                "mekanism:basicblock@2"
            ]
        },
        {
            "x": -3,
            "y": -1,
            "z": 4,
            "elements": [
                "mekanismgenerators:reactorglass@0"
            ]
        },
        {
            "x": 0,
            "y": 1,
            "z": 5,
            "elements": [
                "environmentaltech:pladium@0"
            ]
        },
        {
            "x": -2,
            "y": -3,
            "z": 3,
            "elements": [
                "mekanism:basicblock@2"
            ]
        },
        {
            "x": -1,
            "y": -3,
            "z": 3,
            "elements": [
                "modularmachinery:blockcasing@4"
            ]
        },
        {
            "x": 0,
            "y": -3,
            "z": 3,
            "elements": [
                "modularmachinery:blockcasing@4"
            ]
        },
        {
            "x": 1,
            "y": -3,
            "z": 3,
            "elements": [
                "modularmachinery:blockcasing@4"
            ]
        },
        {
            "x": 4,
            "y": 1,
            "z": 5,
            "elements": [
                "mekanism:basicblock@2"
            ]
        },
        {
            "x": 3,
            "y": -1,
            "z": 4,
            "elements": [
                "mekanismgenerators:reactorglass@0"
            ]
        },
        {
            "x": 2,
            "y": -3,
            "z": 3,
            "elements": [
                "mekanism:basicblock@2"
            ]
        },
        {
            "x": -4,
            "y": 2,
            "z": 5,
            "elements": [
                "environmentaltech:erodium_slab@0"
            ]
        },
        {
            "x": -3,
            "y": 2,
            "z": 5,
            "elements": [
                "modularmachinery:blockcasing@4"
            ]
        },
        {
            "x": -3,
            "y": 0,
            "z": 4,
            "elements": [
                "mekanismgenerators:reactorglass@0"
            ]
        },
        {
            "x": -2,
            "y": 2,
            "z": 5,
            "elements": [
                "modularmachinery:blockcasing@1"
            ]
        },
        {
            "x": -1,
            "y": 2,
            "z": 5,
            "elements": [
                "modularmachinery:blockcasing@3"
            ]
        },
        {
            "x": 0,
            "y": 2,
            "z": 5,
            "elements": [
                "modularmachinery:blockcasing@4"
            ]
        },
        {
            "x": -2,
            "y": -2,
            "z": 3,
            "elements": [
                "mekanismgenerators:reactorglass@0"
            ]
        },
        {
            "x": -1,
            "y": -2,
            "z": 3,
            "elements": [
                "modularmachinery:blockcasing@4"
            ]
        },
        {
            "x": 1,
            "y": 2,
            "z": 5,
            "elements": [
                "modularmachinery:blockcasing@3"
            ]
        },
        {
            "x": 2,
            "y": 2,
            "z": 5,
            "elements": [
                "modularmachinery:blockcasing@1"
            ]
        },
        {
            "x": 3,
            "y": 2,
            "z": 5,
            "elements": [
                "modularmachinery:blockcasing@4"
            ]
        },
        {
            "x": 1,
            "y": -2,
            "z": 3,
            "elements": [
                "modularmachinery:blockcasing@4"
            ]
        },
        {
            "x": 4,
            "y": 2,
            "z": 5,
            "elements": [
                "environmentaltech:erodium_slab@0"
            ]
        },
        {
            "x": 3,
            "y": 0,
            "z": 4,
            "elements": [
                "mekanismgenerators:reactorglass@0"
            ]
        },
        {
            "x": 2,
            "y": -2,
            "z": 3,
            "elements": [
                "mekanismgenerators:reactorglass@0"
            ]
        },
        {
            "x": -3,
            "y": 1,
            "z": 4,
            "elements": [
                "mekanism:basicblock@2"
            ]
        },
        {
            "x": -2,
            "y": -1,
            "z": 3,
            "elements": [
                "mekanismgenerators:reactorglass@0"
            ]
        },
        {
            "x": -1,
            "y": -1,
            "z": 3,
            "elements": [
                "modularmachinery:blockcasing@4"
            ]
        },
        {
            "x": -1,
            "y": -3,
            "z": 2,
            "elements": [
                "modularmachinery:blockcasing@4"
            ]
        },
        {
            "x": 0,
            "y": -3,
            "z": 2,
            "elements": [
                "modularmachinery:blockcasing@1"
            ]
        },
        {
            "x": 1,
            "y": -1,
            "z": 3,
            "elements": [
                "modularmachinery:blockcasing@4"
            ]
        },
        {
            "x": 3,
            "y": 1,
            "z": 4,
            "elements": [
                "mekanism:basicblock@2"
            ]
        },
        {
            "x": 2,
            "y": -1,
            "z": 3,
            "elements": [
                "mekanismgenerators:reactorglass@0"
            ]
        },
        {
            "x": 1,
            "y": -3,
            "z": 2,
            "elements": [
                "modularmachinery:blockcasing@4"
            ]
        },
        {
            "x": -1,
            "y": -3,
            "z": 10,
            "elements": [
                "mekanism:basicblock@2"
            ]
        },
        {
            "x": 0,
            "y": -3,
            "z": 10,
            "elements": [
                "mekanism:basicblock@2"
            ]
        },
        {
            "x": 1,
            "y": -3,
            "z": 10,
            "elements": [
                "mekanism:basicblock@2"
            ]
        },
        {
            "x": -3,
            "y": 2,
            "z": 4,
            "elements": [
                "environmentaltech:erodium_slab@0"
            ]
        },
        {
            "x": -2,
            "y": 2,
            "z": 4,
            "elements": [
                "modularmachinery:blockcasing@1"
            ]
        },
        {
            "x": -2,
            "y": 0,
            "z": 3,
            "elements": [
                "mekanismgenerators:reactorglass@0"
            ]
        },
        {
            "x": -1,
            "y": 2,
            "z": 4,
            "elements": [
                "modularmachinery:blockcasing@1"
            ]
        },
        {
            "x": 0,
            "y": 2,
            "z": 4,
            "elements": [
                "modularmachinery:blockcasing@4"
            ]
        },
        {
            "x": -1,
            "y": 0,
            "z": 3,
            "elements": [
                "modularmachinery:blockcasing@4"
            ]
        },
        {
            "x": -1,
            "y": -2,
            "z": 2,
            "elements": [
                "mekanismgenerators:reactorglass@0"
            ]
        },
        {
            "x": 0,
            "y": 0,
            "z": 3,
            "elements": [
                "modularmachinery:blockcasing@4"
            ]
        },
        {
            "x": 1,
            "y": 2,
            "z": 4,
            "elements": [
                "modularmachinery:blockcasing@1"
            ]
        },
        {
            "x": 2,
            "y": 2,
            "z": 4,
            "elements": [
                "modularmachinery:blockcasing@1"
            ]
        },
        {
            "x": 1,
            "y": 0,
            "z": 3,
            "elements": [
                "modularmachinery:blockcasing@4"
            ]
        },
        {
            "x": 3,
            "y": 2,
            "z": 4,
            "elements": [
                "environmentaltech:erodium_slab@0"
            ]
        },
        {
            "x": 2,
            "y": 0,
            "z": 3,
            "elements": [
                "mekanismgenerators:reactorglass@0"
            ]
        },
        {
            "x": 1,
            "y": -2,
            "z": 2,
            "elements": [
                "mekanismgenerators:reactorglass@0"
            ]
        },
        {
            "x": -1,
            "y": -2,
            "z": 10,
            "elements": [
                "mekanismgenerators:reactorglass@0"
            ]
        },
        {
            "x": 0,
            "y": -2,
            "z": 10,
            "elements": [
                "mekanismgenerators:reactorglass@0"
            ]
        },
        {
            "x": 1,
            "y": -2,
            "z": 10,
            "elements": [
                "mekanismgenerators:reactorglass@0"
            ]
        },
        {
            "x": -2,
            "y": 1,
            "z": 3,
            "elements": [
                "mekanism:basicblock@2"
            ]
        },
        {
            "x": -1,
            "y": 1,
            "z": 3,
            "elements": [
                "modularmachinery:blockcasing@4"
            ]
        },
        {
            "x": 0,
            "y": 1,
            "z": 3,
            "elements": [
                "modularmachinery:blockcasing@4"
            ]
        },
        {
            "x": -1,
            "y": -1,
            "z": 2,
            "elements": [
                "mekanismgenerators:reactorglass@0"
            ]
        },
        {
            "x": -1,
            "y": -3,
            "z": 1,
            "elements": [
                "modularmachinery:blockcasing@4"
            ]
        },
        {
            "x": 1,
            "y": 1,
            "z": 3,
            "elements": [
                "modularmachinery:blockcasing@4"
            ]
        },
        {
            "x": 0,
            "y": -3,
            "z": 1,
            "elements": [
                "modularmachinery:blockcasing@1"
            ]
        },
        {
            "x": 2,
            "y": 1,
            "z": 3,
            "elements": [
                "mekanism:basicblock@2"
            ]
        },
        {
            "x": 1,
            "y": -1,
            "z": 2,
            "elements": [
                "mekanismgenerators:reactorglass@0"
            ]
        },
        {
            "x": 1,
            "y": -3,
            "z": 1,
            "elements": [
                "modularmachinery:blockcasing@4"
            ]
        },
        {
            "x": -2,
            "y": -3,
            "z": 9,
            "elements": [
                "mekanism:basicblock@2"
            ]
        },
        {
            "x": -1,
            "y": -1,
            "z": 10,
            "elements": [
                "mekanismgenerators:reactorglass@0"
            ]
        },
        {
            "x": -1,
            "y": -3,
            "z": 9,
            "elements": [
                "modularmachinery:blockcasing@4"
            ]
        },
        {
            "x": 0,
            "y": -1,
            "z": 10,
            "elements": [
                "mekanismgenerators:reactorglass@0"
            ]
        },
        {
            "x": 0,
            "y": -3,
            "z": 9,
            "elements": [
                "modularmachinery:blockcasing@4"
            ]
        },
        {
            "x": 1,
            "y": -1,
            "z": 10,
            "elements": [
                "mekanismgenerators:reactorglass@0"
            ]
        },
        {
            "x": 1,
            "y": -3,
            "z": 9,
            "elements": [
                "modularmachinery:blockcasing@4"
            ]
        },
        {
            "x": 2,
            "y": -3,
            "z": 9,
            "elements": [
                "mekanism:basicblock@2"
            ]
        },
        {
            "x": -2,
            "y": 2,
            "z": 3,
            "elements": [
                "environmentaltech:erodium_slab@0"
            ]
        },
        {
            "x": -1,
            "y": 2,
            "z": 3,
            "elements": [
                "modularmachinery:blockcasing@4"
            ]
        },
        {
            "x": 0,
            "y": 2,
            "z": 3,
            "elements": [
                "modularmachinery:blockcasing@4"
            ]
        },
        {
            "x": -1,
            "y": 0,
            "z": 2,
            "elements": [
                "modularmachinery:blockcasing@4"
            ]
        },
        {
            "x": 0,
            "y": 0,
            "z": 2,
            "elements": [
                "modularmachinery:blockcasing@3"
            ]
        },
        {
            "x": 1,
            "y": 2,
            "z": 3,
            "elements": [
                "modularmachinery:blockcasing@4"
            ]
        },
        {
            "x": -1,
            "y": -2,
            "z": 1,
            "elements": [
                "mekanismgenerators:reactorglass@0"
            ]
        },
        {
            "x": 2,
            "y": 2,
            "z": 3,
            "elements": [
                "environmentaltech:erodium_slab@0"
            ]
        },
        {
            "x": 1,
            "y": 0,
            "z": 2,
            "elements": [
                "modularmachinery:blockcasing@4"
            ]
        },
        {
            "x": 1,
            "y": -2,
            "z": 1,
            "elements": [
                "mekanismgenerators:reactorglass@0"
            ]
        },
        {
            "x": -2,
            "y": -2,
            "z": 9,
            "elements": [
                "mekanismgenerators:reactorglass@0"
            ]
        },
        {
            "x": -1,
            "y": 0,
            "z": 10,
            "elements": [
                "mekanismgenerators:reactorglass@0"
            ]
        },
        {
            "x": 0,
            "y": 0,
            "z": 10,
            "elements": [
                "mekanismgenerators:reactorglass@0"
            ]
        },
        {
            "x": 1,
            "y": 0,
            "z": 10,
            "elements": [
                "mekanismgenerators:reactorglass@0"
            ]
        },
        {
            "x": 2,
            "y": -2,
            "z": 9,
            "elements": [
                "mekanismgenerators:reactorglass@0"
            ]
        },
        {
            "x": -1,
            "y": 1,
            "z": 2,
            "elements": [
                "mekanism:basicblock@2"
            ]
        },
        {
            "x": 0,
            "y": 1,
            "z": 2,
            "elements": [
                "mekanism:basicblock@2"
            ]
        },
        {
            "x": -1,
            "y": -1,
            "z": 1,
            "elements": [
                "mekanismgenerators:reactorglass@0"
            ]
        },
        {
            "x": 1,
            "y": 1,
            "z": 2,
            "elements": [
                "mekanism:basicblock@2"
            ]
        },
        {
            "x": 1,
            "y": -1,
            "z": 1,
            "elements": [
                "mekanismgenerators:reactorglass@0"
            ]
        },
        {
            "x": -3,
            "y": -3,
            "z": 8,
            "elements": [
                "mekanism:basicblock@2"
            ]
        },
        {
            "x": -2,
            "y": -1,
            "z": 9,
            "elements": [
                "mekanismgenerators:reactorglass@0"
            ]
        },
        {
            "x": -1,
            "y": 1,
            "z": 10,
            "elements": [
                "mekanism:basicblock@2"
            ]
        },
        {
            "x": 0,
            "y": 1,
            "z": 10,
            "elements": [
                "mekanism:basicblock@2"
            ]
        },
        {
            "x": -2,
            "y": -3,
            "z": 8,
            "elements": [
                "modularmachinery:blockcasing@2"
            ]
        },
        {
            "x": -1,
            "y": -3,
            "z": 8,
            "elements": [
                "modularmachinery:blockcasing@2"
            ]
        },
        {
            "x": 1,
            "y": 1,
            "z": 10,
            "elements": [
                "mekanism:basicblock@2"
            ]
        },
        {
            "x": 0,
            "y": -3,
            "z": 8,
            "elements": [
                "modularmachinery:blockcasing@4"
            ]
        },
        {
            "x": 2,
            "y": -1,
            "z": 9,
            "elements": [
                "mekanismgenerators:reactorglass@0"
            ]
        },
        {
            "x": 1,
            "y": -3,
            "z": 8,
            "elements": [
                "modularmachinery:blockcasing@2"
            ]
        },
        {
            "x": 2,
            "y": -3,
            "z": 8,
            "elements": [
                "modularmachinery:blockcasing@2"
            ]
        },
        {
            "x": 3,
            "y": -3,
            "z": 8,
            "elements": [
                "mekanism:basicblock@2"
            ]
        },
        {
            "x": -1,
            "y": 2,
            "z": 2,
            "elements": [
                "environmentaltech:erodium_slab@0"
            ]
        },
        {
            "x": 0,
            "y": 2,
            "z": 2,
            "elements": [
                "environmentaltech:erodium_slab@0"
            ]
        },
        {
            "x": -1,
            "y": 0,
            "z": 1,
            "elements": [
                "modularmachinery:blockcasing@4"
            ]
        },
        {
            "x": 0,
            "y": 0,
            "z": 1,
            "elements": [
                "modularmachinery:blockcasing@3"
            ]
        },
        {
            "x": 1,
            "y": 2,
            "z": 2,
            "elements": [
                "environmentaltech:erodium_slab@0"
            ]
        },
        {
            "x": 1,
            "y": 0,
            "z": 1,
            "elements": [
                "modularmachinery:blockcasing@4"
            ]
        },
        {
            "x": -3,
            "y": -2,
            "z": 8,
            "elements": [
                "mekanismgenerators:reactorglass@0"
            ]
        },
        {
            "x": -2,
            "y": 0,
            "z": 9,
            "elements": [
                "mekanismgenerators:reactorglass@0"
            ]
        },
        {
            "x": -1,
            "y": 2,
            "z": 10,
            "elements": [
                "environmentaltech:erodium_slab@0"
            ]
        },
        {
            "x": 0,
            "y": 2,
            "z": 10,
            "elements": [
                "environmentaltech:erodium_slab@0"
            ]
        },
        {
            "x": 1,
            "y": 2,
            "z": 10,
            "elements": [
                "environmentaltech:erodium_slab@0"
            ]
        },
        {
            "x": 2,
            "y": 0,
            "z": 9,
            "elements": [
                "mekanismgenerators:reactorglass@0"
            ]
        },
        {
            "x": 3,
            "y": -2,
            "z": 8,
            "elements": [
                "mekanismgenerators:reactorglass@0"
            ]
        },
        {
            "x": -1,
            "y": 1,
            "z": 1,
            "elements": [
                "mekanism:basicblock@2"
            ]
        },
        {
            "x": 0,
            "y": 1,
            "z": 1,
            "elements": [
                "mekanism:basicblock@2"
            ]
        },
        {
            "x": 1,
            "y": 1,
            "z": 1,
            "elements": [
                "mekanism:basicblock@2"
            ]
        },
        {
            "x": -4,
            "y": -3,
            "z": 7,
            "elements": [
                "mekanism:basicblock@2"
            ]
        },
        {
            "x": -3,
            "y": -1,
            "z": 8,
            "elements": [
                "mekanismgenerators:reactorglass@0"
            ]
        },
        {
            "x": -2,
            "y": 1,
            "z": 9,
            "elements": [
                "mekanism:basicblock@2"
            ]
        },
        {
            "x": -3,
            "y": -3,
            "z": 7,
            "elements": [
                "modularmachinery:blockcasing@4"
            ]
        },
        {
            "x": -2,
            "y": -3,
            "z": 7,
            "elements": [
                "modularmachinery:blockcasing@2"
            ]
        },
        {
            "x": -1,
            "y": -3,
            "z": 7,
            "elements": [
                "modularmachinery:blockcasing@3"
            ]
        },
        {
            "x": 0,
            "y": -3,
            "z": 7,
            "elements": [
                "modularmachinery:blockcasing@4"
            ]
        },
        {
            "x": 2,
            "y": 1,
            "z": 9,
            "elements": [
                "mekanism:basicblock@2"
            ]
        },
        {
            "x": 1,
            "y": -3,
            "z": 7,
            "elements": [
                "modularmachinery:blockcasing@3"
            ]
        },
        {
            "x": 3,
            "y": -1,
            "z": 8,
            "elements": [
                "mekanismgenerators:reactorglass@0"
            ]
        },
        {
            "x": 2,
            "y": -3,
            "z": 7,
            "elements": [
                "modularmachinery:blockcasing@2"
            ]
        },
        {
            "x": 3,
            "y": -3,
            "z": 7,
            "elements": [
                "modularmachinery:blockcasing@4"
            ]
        },
        {
            "x": 4,
            "y": -3,
            "z": 7,
            "elements": [
                "mekanism:basicblock@2"
            ]
        },
        {
            "x": -1,
            "y": 2,
            "z": 1,
            "elements": [
                "environmentaltech:erodium_slab@0"
            ]
        },
        {
            "x": 0,
            "y": 2,
            "z": 1,
            "elements": [
                "environmentaltech:erodium_slab@0"
            ]
        }
    ]}